1655332175853223833 360526795
1655332176169835624 104597991
1655332176759121009 291030151
1655332177256770621 282518912
1655332177615825149 141284419
1655332177860921971 44670121
1655332179162243427 1096224099
1655332179663558723 296144720
1655332180055313316 182592292
1655332180452917129 192833894
1655332180873251152 215333756
1655332182117432454 1043793858
1655332182370730672 52368797
1655332185756985458 3182782464
1655332185977404957 12744994
1655332186274481448 24973678
1655332186599547124 120719823
1655332186822393339 18588961
1655332187032603199 9720353
1655332187246569895 11224085
1655332187500442667 50945327
1655332188739502470 1036300515
Process StressGenerator-2:
Traceback (most recent call last):
  File "/usr/local/lib/python3.7/site-packages/urllib3/connectionpool.py", line 710, in urlopen
    chunked=chunked,
  File "/usr/local/lib/python3.7/site-packages/urllib3/connectionpool.py", line 449, in _make_request
    six.raise_from(e, None)
  File "<string>", line 3, in raise_from
  File "/usr/local/lib/python3.7/site-packages/urllib3/connectionpool.py", line 444, in _make_request
    httplib_response = conn.getresponse()
  File "/usr/local/lib/python3.7/http/client.py", line 1321, in getresponse
    response.begin()
  File "/usr/local/lib/python3.7/http/client.py", line 296, in begin
    version, status, reason = self._read_status()
  File "/usr/local/lib/python3.7/http/client.py", line 257, in _read_status
    line = str(self.fp.readline(_MAXLINE + 1), "iso-8859-1")
  File "/usr/local/lib/python3.7/socket.py", line 589, in readinto
    return self._sock.recv_into(b)
ConnectionResetError: [Errno 104] Connection reset by peer

During handling of the above exception, another exception occurred:

Traceback (most recent call last):
  File "/usr/local/lib/python3.7/site-packages/requests/adapters.py", line 499, in send
    timeout=timeout,
  File "/usr/local/lib/python3.7/site-packages/urllib3/connectionpool.py", line 786, in urlopen
    method, url, error=e, _pool=self, _stacktrace=sys.exc_info()[2]
  File "/usr/local/lib/python3.7/site-packages/urllib3/util/retry.py", line 550, in increment
    raise six.reraise(type(error), error, _stacktrace)
  File "/usr/local/lib/python3.7/site-packages/urllib3/packages/six.py", line 769, in reraise
    raise value.with_traceback(tb)
  File "/usr/local/lib/python3.7/site-packages/urllib3/connectionpool.py", line 710, in urlopen
    chunked=chunked,
  File "/usr/local/lib/python3.7/site-packages/urllib3/connectionpool.py", line 449, in _make_request
    six.raise_from(e, None)
  File "<string>", line 3, in raise_from
  File "/usr/local/lib/python3.7/site-packages/urllib3/connectionpool.py", line 444, in _make_request
    httplib_response = conn.getresponse()
  File "/usr/local/lib/python3.7/http/client.py", line 1321, in getresponse
    response.begin()
  File "/usr/local/lib/python3.7/http/client.py", line 296, in begin
    version, status, reason = self._read_status()
  File "/usr/local/lib/python3.7/http/client.py", line 257, in _read_status
    line = str(self.fp.readline(_MAXLINE + 1), "iso-8859-1")
  File "/usr/local/lib/python3.7/socket.py", line 589, in readinto
    return self._sock.recv_into(b)
urllib3.exceptions.ProtocolError: ('Connection aborted.', ConnectionResetError(104, 'Connection reset by peer'))

During handling of the above exception, another exception occurred:

Traceback (most recent call last):
  File "/usr/local/lib/python3.7/multiprocessing/process.py", line 297, in _bootstrap
    self.run()
  File "app.py", line 40, in run
    self._write_work()
  File "app.py", line 51, in _write_work
    self.do_post_request.perform(encode_bytes_as_base64)
  File "/app/models/simple_http_log_client.py", line 11, in perform
    return self._simple_requests_scenario(body_json_content)
  File "/app/models/simple_http_log_client.py", line 16, in _simple_requests_scenario
    return self.session.post(f"{self.api_url}/insert", body_json_content)
  File "/usr/local/lib/python3.7/site-packages/requests/sessions.py", line 635, in post
    return self.request("POST", url, data=data, json=json, **kwargs)
  File "/usr/local/lib/python3.7/site-packages/requests/sessions.py", line 587, in request
    resp = self.send(prep, **send_kwargs)
  File "/usr/local/lib/python3.7/site-packages/requests/sessions.py", line 701, in send
    r = adapter.send(request, **kwargs)
  File "/usr/local/lib/python3.7/site-packages/requests/adapters.py", line 547, in send
    raise ConnectionError(err, request=request)
requests.exceptions.ConnectionError: ('Connection aborted.', ConnectionResetError(104, 'Connection reset by peer'))
1655332188969591680 20135346
1655332189188815263 18302678
1655332189400269628 10935982
1655332189663127473 60081513
1655332189878663174 15130248
1655332190155048890 63890035
1655332190377931466 22476317
1655332190603466874 16225660
1655332190829983659 21688794
1655332191058571743 24032899
1655332191279638344 18055240
1655332191564301558 84015628
1655332191788661118 19499252
1655332192011553300 15916330
1655332192367870301 118375418
1655332192669582456 96610099
1655332192886935291 15724645
1655332193100476633 9413909
1655332193449998158 100488101
1655332193677964534 24470982
1655332194052674983 100862245
1655332194352563063 95758493
1655332197701963484 3149000174
1655332197950860369 48216505
1655332198165805227 13685449
1655332198465921067 98615462
1655332198852379036 181505626
1655332199173431645 120603849
1655332199463672543 89853529
1655332199952716090 276397768
1655332200353770563 199891383
1655332200678942884 120145532
1655332200981442718 9282116
1655332201279663742 30133141
1655332201654767387 100708523
1655332201952170391 86065308
1655332202253353747 100763488
1655332202652637821 103138742
1655332203057567825 195214732
1655332204358730982 1092963146
1655332204581101596 17581926
1655332205054076330 203390216
1655332205463578472 203309355
1655332205698505105 18649502
1655332206070674030 118563515
1655332206369125367 11645252
1655332206660707912 90968606
1655332206894031726 30542498
1655332207109410772 14944434
1655332208361221747 1048663644
1655332208581755227 20035315
1655332208852912807 70710211
1655332209073732163 14187854
1655332209294020431 19866593
1655332210599135813 1104727346
1655332210813056501 13308907
1655332211029402123 13419663
1655332211298608864 68796083
1655332211512744944 13738133
1655332211751550380 38363025
1655332211969823318 17841243
1655332212258476324 88220904
1655332212570574399 106160113
1655332213994234826 1141487729
1655332214257661551 62995568
1655332214477320638 19243156
1655332215717869916 1036519585
1655332215935659882 13632780
1655332216153071163 12775466
1655332216372682142 15880849
1655332216597415952 24340694
1655332216848843851 50776712
1655332217068667868 19208391
1655332217464372082 191386207
1655332217759994515 88519966
1655332217981490394 13354982
1655332218272932413 23486305
1655332218654015613 173621053
1655332220067990958 1204043830
1655332220291900487 21223387
1655332220504092760 9437087
1655332220717470429 10615352
1655332221166236032 198093244
1655332221383418846 9473128
1655332221758605587 109106183
1655332221974909283 11026241
1655332222185485741 9633679
1655332222453938545 68055790
1655332222670055862 15430892
1655332223068893612 198156560
1655332223376217701 97113548
1655332223684128673 34610462
1655332224075268359 121886783
1655332224289023526 13353882
1655332224559420320 69992969
1655332224860037739 99603550
1655332225072964716 11448056
1655332225552332620 202828188
1655332225877513822 124729493
1655332226098425772 20507519
1655332226360791589 61914009
1655332226589458261 25220720
1655332226867857551 77995923
1655332228266553297 1193826797
1655332228661696633 180073844
1655332228970458485 105041288
1655332229270868145 99988168
1655332229572854947 93659369
1655332230158680188 101346622
1655332230597705033 233530174
1655332230877450337 23436126
1655332231169551280 91688498
1655332231470876492 97079447
1655332232862636566 1106638632
1655332233172016479 103061772
1655332233567213804 194797395
1655332234899176772 1119343859
1655332235130858130 31250642
1655332235359818775 10022095
1655332235574118315 10025107
1655332235790538896 12124639
1655332237091833908 1096959745
1655332237304053642 9420650
1655332237568882487 15229868
1655332237946992302 175143337
1655332238274071737 121972888
1655332238494257919 19743290
1655332238765029620 12786218
1655332238981038270 11644101
1655332239280197904 27386008
1655332239569183946 14866262
1655332239871083858 100012086
1655332240354854800 271319571
1655332240653224061 97926650
1655332240959594616 93986564
1655332241173887254 12075073
1655332241494996065 120673640
1655332241858776418 97651769
1655332242252702377 193186904
1655332243592308365 1138426359
1655332244066113297 265829342
1655332244366168958 86207314
1655332244583267788 15204556
1655332244864440321 76897026
1655332245260958313 187152127
1655332245672482855 207305117
1655332245891225946 15409312
1655332246168490041 18673589
1655332246473222695 104004166
1655332246699242659 25631328
1655332246993437155 92612571
1655332247220810456 26971372
1655332247462012425 32272023
1655332247679078157 16650649
1655332248063423447 101902618
1655332248366513018 94577683
1655332248652636033 79389481
1655332248873723751 20658265
1655332249175203756 101065302
1655332249470064171 13440594
1655332249781079492 105217368
1655332250071245004 89265048
1655332250373049717 97390481
1655332250672772296 99324895
1655332251052585123 179381456
1655332251464051401 210399889
1655332251679628565 13083964
1655332251961051536 80888329
1655332252273352407 111863563
1655332253651322836 1177528647
1655332253874799093 22957989
1655332254258730644 98920732
1655332254570475514 110873251
1655332255955606208 1180870265
1655332256467963100 306005845
Process StressGenerator-13:
Traceback (most recent call last):
  File "/usr/local/lib/python3.7/site-packages/urllib3/connectionpool.py", line 710, in urlopen
    chunked=chunked,
  File "/usr/local/lib/python3.7/site-packages/urllib3/connectionpool.py", line 449, in _make_request
    six.raise_from(e, None)
  File "<string>", line 3, in raise_from
  File "/usr/local/lib/python3.7/site-packages/urllib3/connectionpool.py", line 444, in _make_request
    httplib_response = conn.getresponse()
  File "/usr/local/lib/python3.7/http/client.py", line 1321, in getresponse
    response.begin()
  File "/usr/local/lib/python3.7/http/client.py", line 296, in begin
    version, status, reason = self._read_status()
  File "/usr/local/lib/python3.7/http/client.py", line 257, in _read_status
    line = str(self.fp.readline(_MAXLINE + 1), "iso-8859-1")
  File "/usr/local/lib/python3.7/socket.py", line 589, in readinto
    return self._sock.recv_into(b)
ConnectionResetError: [Errno 104] Connection reset by peer

During handling of the above exception, another exception occurred:

Traceback (most recent call last):
  File "/usr/local/lib/python3.7/site-packages/requests/adapters.py", line 499, in send
    timeout=timeout,
  File "/usr/local/lib/python3.7/site-packages/urllib3/connectionpool.py", line 786, in urlopen
    method, url, error=e, _pool=self, _stacktrace=sys.exc_info()[2]
  File "/usr/local/lib/python3.7/site-packages/urllib3/util/retry.py", line 550, in increment
    raise six.reraise(type(error), error, _stacktrace)
  File "/usr/local/lib/python3.7/site-packages/urllib3/packages/six.py", line 769, in reraise
    raise value.with_traceback(tb)
  File "/usr/local/lib/python3.7/site-packages/urllib3/connectionpool.py", line 710, in urlopen
    chunked=chunked,
  File "/usr/local/lib/python3.7/site-packages/urllib3/connectionpool.py", line 449, in _make_request
    six.raise_from(e, None)
  File "<string>", line 3, in raise_from
  File "/usr/local/lib/python3.7/site-packages/urllib3/connectionpool.py", line 444, in _make_request
    httplib_response = conn.getresponse()
1655332257910687330 1160602240
  File "/usr/local/lib/python3.7/http/client.py", line 1321, in getresponse
    response.begin()
  File "/usr/local/lib/python3.7/http/client.py", line 296, in begin
    version, status, reason = self._read_status()
  File "/usr/local/lib/python3.7/http/client.py", line 257, in _read_status
    line = str(self.fp.readline(_MAXLINE + 1), "iso-8859-1")
  File "/usr/local/lib/python3.7/socket.py", line 589, in readinto
    return self._sock.recv_into(b)
urllib3.exceptions.ProtocolError: ('Connection aborted.', ConnectionResetError(104, 'Connection reset by peer'))

During handling of the above exception, another exception occurred:

Traceback (most recent call last):
  File "/usr/local/lib/python3.7/multiprocessing/process.py", line 297, in _bootstrap
    self.run()
  File "app.py", line 40, in run
    self._write_work()
  File "app.py", line 51, in _write_work
    self.do_post_request.perform(encode_bytes_as_base64)
  File "/app/models/simple_http_log_client.py", line 11, in perform
    return self._simple_requests_scenario(body_json_content)
  File "/app/models/simple_http_log_client.py", line 16, in _simple_requests_scenario
    return self.session.post(f"{self.api_url}/insert", body_json_content)
  File "/usr/local/lib/python3.7/site-packages/requests/sessions.py", line 635, in post
    return self.request("POST", url, data=data, json=json, **kwargs)
  File "/usr/local/lib/python3.7/site-packages/requests/sessions.py", line 587, in request
    resp = self.send(prep, **send_kwargs)
  File "/usr/local/lib/python3.7/site-packages/requests/sessions.py", line 701, in send
    r = adapter.send(request, **kwargs)
  File "/usr/local/lib/python3.7/site-packages/requests/adapters.py", line 547, in send
    raise ConnectionError(err, request=request)
requests.exceptions.ConnectionError: ('Connection aborted.', ConnectionResetError(104, 'Connection reset by peer'))
1655332258166672854 48953932
1655332258653381924 282228922
1655332258866809780 10602000
1655332259076646460 9434955
1655332259289612635 10225563
1655332259501580761 11562182
1655332259751238821 46755890
1655332260057763508 96288847
1655332260278059665 15955492
1655332260560504842 81242519
1655332260869873259 108093294
1655332261152666894 82387406
1655332261470854487 117786088
1655332261975131313 210348855
1655332262374865639 195396158
1655332262588917606 13635442
1655332262974064756 118125971
1655332264199576693 1024563763
1655332265554183821 1154306836
