1655693219274359914 198796650
1655693219493393645 10069935
1655693219781265494 78765725
1655693219995560248 9299276
1655693220287911508 89774715
1655693220694742538 198092731
1655693222180334061 1187233000
1655693222393031537 12364274
1655693222674822264 77414138
1655693222895620163 9622320
1655693223213630626 11734529
1655693223472755250 57832091
1655693223689660381 6235200
1655693223919726603 24540813
1655693224171304984 38513089
1655693224483760424 105825668
1655693224700623936 14425065
1655693224911787807 8036704
1655693225119796691 4330038
1655693225326237127 3450746
1655693225532124105 3360256
1655693225977158820 197631274
1655693226275766130 98291711
1655693226500169673 13747918
1655693226706112752 3076133
1655693226977171780 3984774
1655693227287793036 105731028
1655693227509665182 9732776
1655693227771631681 54272663
1655693227978572331 4576983
1655693228188691209 7282493
1655693228399201040 9491631
1655693228687836338 17910225
1655693228985708443 94517573
1655693229367911241 181212835
1655693229572285008 4035006
1655693229776519894 3870681
1655693229980570092 3614304
1655693230187547293 4408193
1655693230393640994 3684877
1655693231601179890 1006992472
1655693231808110774 5848545
1655693232092331819 81432290
1655693232370163316 75402190
1655693232595046058 14250129
1655693232868633274 70292632
1655693233080216266 5203042
1655693233382220395 101650227
1655693233598953391 14837293
1655693233808522258 3776263
1655693234030731359 14792624
1655693234289609963 19672400
1655693234499310864 9378175
Process StressGenerator-9:
Traceback (most recent call last):
  File "/usr/local/lib/python3.7/site-packages/urllib3/connectionpool.py", line 710, in urlopen
    chunked=chunked,
  File "/usr/local/lib/python3.7/site-packages/urllib3/connectionpool.py", line 449, in _make_request
    six.raise_from(e, None)
  File "<string>", line 3, in raise_from
  File "/usr/local/lib/python3.7/site-packages/urllib3/connectionpool.py", line 444, in _make_request
    httplib_response = conn.getresponse()
  File "/usr/local/lib/python3.7/http/client.py", line 1321, in getresponse
    response.begin()
  File "/usr/local/lib/python3.7/http/client.py", line 296, in begin
    version, status, reason = self._read_status()
  File "/usr/local/lib/python3.7/http/client.py", line 257, in _read_status
    line = str(self.fp.readline(_MAXLINE + 1), "iso-8859-1")
  File "/usr/local/lib/python3.7/socket.py", line 589, in readinto
    return self._sock.recv_into(b)
ConnectionResetError: [Errno 104] Connection reset by peer

During handling of the above exception, another exception occurred:

Traceback (most recent call last):
  File "/usr/local/lib/python3.7/site-packages/requests/adapters.py", line 499, in send
    timeout=timeout,
  File "/usr/local/lib/python3.7/site-packages/urllib3/connectionpool.py", line 786, in urlopen
    method, url, error=e, _pool=self, _stacktrace=sys.exc_info()[2]
  File "/usr/local/lib/python3.7/site-packages/urllib3/util/retry.py", line 550, in increment
    raise six.reraise(type(error), error, _stacktrace)
  File "/usr/local/lib/python3.7/site-packages/urllib3/packages/six.py", line 769, in reraise
    raise value.with_traceback(tb)
  File "/usr/local/lib/python3.7/site-packages/urllib3/connectionpool.py", line 710, in urlopen
    chunked=chunked,
  File "/usr/local/lib/python3.7/site-packages/urllib3/connectionpool.py", line 449, in _make_request
    six.raise_from(e, None)
  File "<string>", line 3, in raise_from
  File "/usr/local/lib/python3.7/site-packages/urllib3/connectionpool.py", line 444, in _make_request
    httplib_response = conn.getresponse()
  File "/usr/local/lib/python3.7/http/client.py", line 1321, in getresponse
    response.begin()
  File "/usr/local/lib/python3.7/http/client.py", line 296, in begin
    version, status, reason = self._read_status()
  File "/usr/local/lib/python3.7/http/client.py", line 257, in _read_status
    line = str(self.fp.readline(_MAXLINE + 1), "iso-8859-1")
  File "/usr/local/lib/python3.7/socket.py", line 589, in readinto
    return self._sock.recv_into(b)
urllib3.exceptions.ProtocolError: ('Connection aborted.', ConnectionResetError(104, 'Connection reset by peer'))

During handling of the above exception, another exception occurred:

Traceback (most recent call last):
  File "/usr/local/lib/python3.7/multiprocessing/process.py", line 297, in _bootstrap
    self.run()
  File "app.py", line 43, in run
    self._write_work()
  File "app.py", line 54, in _write_work
    self.do_post_request.perform(encode_bytes_as_base64)
  File "/app/models/simple_http_log_client.py", line 11, in perform
    return self._simple_requests_scenario(body_json_content)
  File "/app/models/simple_http_log_client.py", line 16, in _simple_requests_scenario
    return self.session.post(f"{self.api_url}/insert", body_json_content)
  File "/usr/local/lib/python3.7/site-packages/requests/sessions.py", line 635, in post
    return self.request("POST", url, data=data, json=json, **kwargs)
  File "/usr/local/lib/python3.7/site-packages/requests/sessions.py", line 587, in request
    resp = self.send(prep, **send_kwargs)
  File "/usr/local/lib/python3.7/site-packages/requests/sessions.py", line 701, in send
    r = adapter.send(request, **kwargs)
  File "/usr/local/lib/python3.7/site-packages/requests/adapters.py", line 547, in send
    raise ConnectionError(err, request=request)
requests.exceptions.ConnectionError: ('Connection aborted.', ConnectionResetError(104, 'Connection reset by peer'))
1655693236035950919 1335992397
1655693236292213124 18737782
1655693236576823363 82840097
1655693236793889652 16755882
1655693237168599879 96590599
1655693237387731476 18725294
1655693237592497499 4268784
1655693237882693192 85728936
1655693239182737444 1097131159
1655693239405000621 14815366
1655693239681696126 10320350
1655693240972205079 1089823857
1655693241182906392 6549793
1655693241488740520 102809488
1655693241868340665 98685482
1655693242089664065 9467321
1655693242377237957 80490593
1655693242586635785 8712282
1655693242869437436 81849830
1655693243078099114 8353729
1655693243285861945 4106524
1655693243770589545 88123548
1655693243975778384 4977195
1655693244179393221 3159587
1655693244473109524 84586106
1655693244695080550 11351740
1655693246068820225 1169545970
1655693246284101781 14083673
1655693246578777580 81844667
1655693246793712247 13922189
1655693248113042948 1028857521
1655693248477829514 88248322
1655693248888258504 188849956
1655693249171862165 71931454
1655693249385742782 8500956
1655693249669658903 76689484
1655693249879251780 8319420
1655693250087825333 4913709
1655693250296210057 3926733
1655693250506288461 6129439
1655693250712593418 5607951
1655693250993200089 12266960
1655693251282381017 9257432
1655693251491805118 6872666
1655693251878695140 93158502
1655693252194584284 107636598
1655693252597326126 105889893
1655693252868758741 65261693
1655693253079235067 5430129
1655693253288133841 4297768
Process StressGenerator-15:
Process StressGenerator-18:
Traceback (most recent call last):
  File "/usr/local/lib/python3.7/site-packages/urllib3/connectionpool.py", line 710, in urlopen
    chunked=chunked,
  File "/usr/local/lib/python3.7/site-packages/urllib3/connectionpool.py", line 449, in _make_request
    six.raise_from(e, None)
  File "<string>", line 3, in raise_from
  File "/usr/local/lib/python3.7/site-packages/urllib3/connectionpool.py", line 444, in _make_request
    httplib_response = conn.getresponse()
  File "/usr/local/lib/python3.7/http/client.py", line 1321, in getresponse
    response.begin()
  File "/usr/local/lib/python3.7/http/client.py", line 296, in begin
    version, status, reason = self._read_status()
  File "/usr/local/lib/python3.7/http/client.py", line 257, in _read_status
    line = str(self.fp.readline(_MAXLINE + 1), "iso-8859-1")
  File "/usr/local/lib/python3.7/socket.py", line 589, in readinto
    return self._sock.recv_into(b)
ConnectionResetError: [Errno 104] Connection reset by peer

During handling of the above exception, another exception occurred:

Traceback (most recent call last):
  File "/usr/local/lib/python3.7/site-packages/requests/adapters.py", line 499, in send
    timeout=timeout,
  File "/usr/local/lib/python3.7/site-packages/urllib3/connectionpool.py", line 786, in urlopen
    method, url, error=e, _pool=self, _stacktrace=sys.exc_info()[2]
  File "/usr/local/lib/python3.7/site-packages/urllib3/util/retry.py", line 550, in increment
    raise six.reraise(type(error), error, _stacktrace)
  File "/usr/local/lib/python3.7/site-packages/urllib3/packages/six.py", line 769, in reraise
    raise value.with_traceback(tb)
  File "/usr/local/lib/python3.7/site-packages/urllib3/connectionpool.py", line 710, in urlopen
    chunked=chunked,
  File "/usr/local/lib/python3.7/site-packages/urllib3/connectionpool.py", line 449, in _make_request
    six.raise_from(e, None)
  File "<string>", line 3, in raise_from
  File "/usr/local/lib/python3.7/site-packages/urllib3/connectionpool.py", line 444, in _make_request
    httplib_response = conn.getresponse()
  File "/usr/local/lib/python3.7/http/client.py", line 1321, in getresponse
    response.begin()
  File "/usr/local/lib/python3.7/http/client.py", line 296, in begin
    version, status, reason = self._read_status()
  File "/usr/local/lib/python3.7/http/client.py", line 257, in _read_status
    line = str(self.fp.readline(_MAXLINE + 1), "iso-8859-1")
  File "/usr/local/lib/python3.7/socket.py", line 589, in readinto
    return self._sock.recv_into(b)
urllib3.exceptions.ProtocolError: ('Connection aborted.', ConnectionResetError(104, 'Connection reset by peer'))

During handling of the above exception, another exception occurred:

Traceback (most recent call last):
  File "/usr/local/lib/python3.7/multiprocessing/process.py", line 297, in _bootstrap
    self.run()
  File "app.py", line 43, in run
    self._write_work()
  File "app.py", line 54, in _write_work
    self.do_post_request.perform(encode_bytes_as_base64)
  File "/app/models/simple_http_log_client.py", line 11, in perform
    return self._simple_requests_scenario(body_json_content)
Traceback (most recent call last):
  File "/usr/local/lib/python3.7/site-packages/urllib3/connectionpool.py", line 710, in urlopen
    chunked=chunked,
  File "/usr/local/lib/python3.7/site-packages/urllib3/connectionpool.py", line 449, in _make_request
    six.raise_from(e, None)
  File "<string>", line 3, in raise_from
  File "/usr/local/lib/python3.7/site-packages/urllib3/connectionpool.py", line 444, in _make_request
    httplib_response = conn.getresponse()
  File "/usr/local/lib/python3.7/http/client.py", line 1321, in getresponse
    response.begin()
  File "/usr/local/lib/python3.7/http/client.py", line 296, in begin
    version, status, reason = self._read_status()
  File "/usr/local/lib/python3.7/http/client.py", line 257, in _read_status
    line = str(self.fp.readline(_MAXLINE + 1), "iso-8859-1")
  File "/usr/local/lib/python3.7/socket.py", line 589, in readinto
    return self._sock.recv_into(b)
ConnectionResetError: [Errno 104] Connection reset by peer

During handling of the above exception, another exception occurred:

Traceback (most recent call last):
  File "/usr/local/lib/python3.7/site-packages/requests/adapters.py", line 499, in send
    timeout=timeout,
  File "/usr/local/lib/python3.7/site-packages/urllib3/connectionpool.py", line 786, in urlopen
    method, url, error=e, _pool=self, _stacktrace=sys.exc_info()[2]
  File "/usr/local/lib/python3.7/site-packages/urllib3/util/retry.py", line 550, in increment
    raise six.reraise(type(error), error, _stacktrace)
  File "/usr/local/lib/python3.7/site-packages/urllib3/packages/six.py", line 769, in reraise
    raise value.with_traceback(tb)
  File "/usr/local/lib/python3.7/site-packages/urllib3/connectionpool.py", line 710, in urlopen
    chunked=chunked,
  File "/usr/local/lib/python3.7/site-packages/urllib3/connectionpool.py", line 449, in _make_request
    six.raise_from(e, None)
  File "<string>", line 3, in raise_from
  File "/usr/local/lib/python3.7/site-packages/urllib3/connectionpool.py", line 444, in _make_request
    httplib_response = conn.getresponse()
  File "/usr/local/lib/python3.7/http/client.py", line 1321, in getresponse
    response.begin()
  File "/usr/local/lib/python3.7/http/client.py", line 296, in begin
    version, status, reason = self._read_status()
  File "/usr/local/lib/python3.7/http/client.py", line 257, in _read_status
    line = str(self.fp.readline(_MAXLINE + 1), "iso-8859-1")
  File "/usr/local/lib/python3.7/socket.py", line 589, in readinto
    return self._sock.recv_into(b)
urllib3.exceptions.ProtocolError: ('Connection aborted.', ConnectionResetError(104, 'Connection reset by peer'))

During handling of the above exception, another exception occurred:

Traceback (most recent call last):
  File "/usr/local/lib/python3.7/multiprocessing/process.py", line 297, in _bootstrap
    self.run()
  File "app.py", line 43, in run
    self._write_work()
  File "app.py", line 54, in _write_work
    self.do_post_request.perform(encode_bytes_as_base64)
  File "/app/models/simple_http_log_client.py", line 11, in perform
    return self._simple_requests_scenario(body_json_content)
  File "/app/models/simple_http_log_client.py", line 16, in _simple_requests_scenario
    return self.session.post(f"{self.api_url}/insert", body_json_content)
  File "/usr/local/lib/python3.7/site-packages/requests/sessions.py", line 635, in post
    return self.request("POST", url, data=data, json=json, **kwargs)
  File "/usr/local/lib/python3.7/site-packages/requests/sessions.py", line 587, in request
    resp = self.send(prep, **send_kwargs)
  File "/usr/local/lib/python3.7/site-packages/requests/sessions.py", line 701, in send
    r = adapter.send(request, **kwargs)
  File "/usr/local/lib/python3.7/site-packages/requests/adapters.py", line 547, in send
    raise ConnectionError(err, request=request)
requests.exceptions.ConnectionError: ('Connection aborted.', ConnectionResetError(104, 'Connection reset by peer'))
  File "/app/models/simple_http_log_client.py", line 16, in _simple_requests_scenario
    return self.session.post(f"{self.api_url}/insert", body_json_content)
  File "/usr/local/lib/python3.7/site-packages/requests/sessions.py", line 635, in post
    return self.request("POST", url, data=data, json=json, **kwargs)
  File "/usr/local/lib/python3.7/site-packages/requests/sessions.py", line 587, in request
    resp = self.send(prep, **send_kwargs)
  File "/usr/local/lib/python3.7/site-packages/requests/sessions.py", line 701, in send
    r = adapter.send(request, **kwargs)
  File "/usr/local/lib/python3.7/site-packages/requests/adapters.py", line 547, in send
    raise ConnectionError(err, request=request)
requests.exceptions.ConnectionError: ('Connection aborted.', ConnectionResetError(104, 'Connection reset by peer'))
1655693253579060387 86268640
1655693253794436253 7683975
1655693254073105478 75125766
1655693254288139602 5103336
1655693254494200962 5708268
1655693254705344041 9401414
1655693254980851408 70790319
Process StressGenerator-29:
Traceback (most recent call last):
  File "/usr/local/lib/python3.7/site-packages/urllib3/connectionpool.py", line 710, in urlopen
    chunked=chunked,
  File "/usr/local/lib/python3.7/site-packages/urllib3/connectionpool.py", line 449, in _make_request
    six.raise_from(e, None)
  File "<string>", line 3, in raise_from
  File "/usr/local/lib/python3.7/site-packages/urllib3/connectionpool.py", line 444, in _make_request
    httplib_response = conn.getresponse()
  File "/usr/local/lib/python3.7/http/client.py", line 1321, in getresponse
    response.begin()
  File "/usr/local/lib/python3.7/http/client.py", line 296, in begin
    version, status, reason = self._read_status()
  File "/usr/local/lib/python3.7/http/client.py", line 257, in _read_status
    line = str(self.fp.readline(_MAXLINE + 1), "iso-8859-1")
  File "/usr/local/lib/python3.7/socket.py", line 589, in readinto
    return self._sock.recv_into(b)
ConnectionResetError: [Errno 104] Connection reset by peer

During handling of the above exception, another exception occurred:

Traceback (most recent call last):
  File "/usr/local/lib/python3.7/site-packages/requests/adapters.py", line 499, in send
    timeout=timeout,
  File "/usr/local/lib/python3.7/site-packages/urllib3/connectionpool.py", line 786, in urlopen
    method, url, error=e, _pool=self, _stacktrace=sys.exc_info()[2]
  File "/usr/local/lib/python3.7/site-packages/urllib3/util/retry.py", line 550, in increment
    raise six.reraise(type(error), error, _stacktrace)
  File "/usr/local/lib/python3.7/site-packages/urllib3/packages/six.py", line 769, in reraise
    raise value.with_traceback(tb)
  File "/usr/local/lib/python3.7/site-packages/urllib3/connectionpool.py", line 710, in urlopen
    chunked=chunked,
  File "/usr/local/lib/python3.7/site-packages/urllib3/connectionpool.py", line 449, in _make_request
    six.raise_from(e, None)
  File "<string>", line 3, in raise_from
  File "/usr/local/lib/python3.7/site-packages/urllib3/connectionpool.py", line 444, in _make_request
    httplib_response = conn.getresponse()
  File "/usr/local/lib/python3.7/http/client.py", line 1321, in getresponse
    response.begin()
  File "/usr/local/lib/python3.7/http/client.py", line 296, in begin
    version, status, reason = self._read_status()
  File "/usr/local/lib/python3.7/http/client.py", line 257, in _read_status
    line = str(self.fp.readline(_MAXLINE + 1), "iso-8859-1")
  File "/usr/local/lib/python3.7/socket.py", line 589, in readinto
    return self._sock.recv_into(b)
urllib3.exceptions.ProtocolError: ('Connection aborted.', ConnectionResetError(104, 'Connection reset by peer'))

During handling of the above exception, another exception occurred:

Traceback (most recent call last):
  File "/usr/local/lib/python3.7/multiprocessing/process.py", line 297, in _bootstrap
    self.run()
  File "app.py", line 43, in run
    self._write_work()
  File "app.py", line 54, in _write_work
    self.do_post_request.perform(encode_bytes_as_base64)
  File "/app/models/simple_http_log_client.py", line 11, in perform
    return self._simple_requests_scenario(body_json_content)
  File "/app/models/simple_http_log_client.py", line 16, in _simple_requests_scenario
    return self.session.post(f"{self.api_url}/insert", body_json_content)
  File "/usr/local/lib/python3.7/site-packages/requests/sessions.py", line 635, in post
    return self.request("POST", url, data=data, json=json, **kwargs)
  File "/usr/local/lib/python3.7/site-packages/requests/sessions.py", line 587, in request
    resp = self.send(prep, **send_kwargs)
  File "/usr/local/lib/python3.7/site-packages/requests/sessions.py", line 701, in send
    r = adapter.send(request, **kwargs)
  File "/usr/local/lib/python3.7/site-packages/requests/adapters.py", line 547, in send
    raise ConnectionError(err, request=request)
requests.exceptions.ConnectionError: ('Connection aborted.', ConnectionResetError(104, 'Connection reset by peer'))
1655693256268775461 1087579423
1655693256481473985 4768586
1655693256696542965 13578764
1655693256978443489 7419146
1655693257186853355 6929558
1655693257489669033 92866303
1655693257769032044 69444450
1655693257983443688 9339272
1655693258281329145 7869754
1655693258496302193 6793017
1655693258789902435 19546316
1655693259073845540 78921489
1655693259281057134 6088641
1655693259568761844 80561269
1655693259787413868 13945982
1655693259991325946 3428181
1655693260196714568 3133647
1655693260475776966 8040961
1655693260771716334 88789998
1655693260986702932 11763042
1655693261272427993 85159825
1655693261486720845 4896756
1655693261709606672 22507718
1655693261913496449 3566007
1655693262119371302 3651986
1655693262381405581 10538254
1655693262597519511 11551919
1655693262885914678 14130916
1655693263196667628 103126943
1655693263403547735 5600764
1655693263676435172 70201016
1655693263891619415 14585068
1655693264176020744 78381297
1655693264386178665 6453023
1655693264689929454 102785183
1655693264909741312 19170380
1655693265117939352 4263289
1655693265324580509 6163122
1655693265527847786 2911623
1655693265777811263 8183051
1655693265995574199 4619472
1655693267250543948 1054613271
1655693267472654018 20519306
1655693267686702051 8780413
1655693267970652008 83033718
1655693268269736587 87507353
1655693268572241036 96435695
1655693268783377529 9134318
1655693268994945167 11267948
1655693269201225550 3284571
1655693269484755376 72721482
1655693269775453886 86701095
1655693269983557830 6425350
1655693270202650173 10685077
1655693270408507669 3455284
1655693270682413873 12475853
1655693270975157972 88513667
1655693271276538742 91358085
1655693271494297331 5340224
1655693271775792699 78252421
1655693271993415002 13979241
1655693272201369974 3332545
1655693272487571951 15052195
1655693272786104962 5873048
1655693273278627396 280651758
1655693273493336661 11259428
1655693273709459455 11529144
1655693273917758209 7627405
1655693274130821954 5772874
1655693274341499023 4065881
1655693274573528252 31722636
1655693274783676194 7865774
1655693274991755541 3831883
1655693275204122197 9202093
1655693275489802719 16555925
1655693275782368237 14625274
1655693275989285638 4341471
1655693276271820937 82240809
1655693276482576650 5042930
1655693276874484271 97691512
1655693277089853490 9736874
1655693277384647827 9950548
1655693277787203410 181614915
1655693278090969322 94871765
1655693278302799205 10868828
1655693278597113809 26102913
1655693278893713659 21943556
1655693280111207594 1014079186
1655693280322538726 5927748
1655693281586010181 1061094549
1655693281794860023 7926989
1655693282068993682 73057549
1655693282284024520 13469398
1655693282487819165 3381607
1655693282771776519 78314352
1655693283192777346 207574927
1655693283398592836 3124213
1655693283673312561 74362819
1655693283888322788 14702709
1655693284107798695 17310365
1655693284339614317 17333152
1655693284544010209 3049003
1655693284770556361 26198828
1655693284986810458 8410832
1655693285193762138 6812720
1655693285478924018 84414398
1655693285682786734 3562807
1655693285983078935 95838322
1655693286197267300 8149811
1655693286406127601 8009831
1655693286614187294 3889821
1655693286820007560 2794666
1655693287070537830 49618255
1655693287274821831 3871713
1655693287487487731 11804385
1655693287713368501 10579608
1655693287928982342 4718085
1655693288170585397 31221942
1655693288377197171 3621626
1655693288582822642 3206251
1655693288788381616 5236525
1655693289077717467 76362303
1655693289294667624 16726541
1655693289575800955 79845663
1655693289780678642 4441619
1655693289986998809 6075940
1655693290195314143 3479077
1655693290401165437 3640485
1655693290605469622 3820915
1655693290879703177 9762366
1655693291085919068 5986297
1655693291369989888 83055122
1655693291776847419 192811676
1655693292085737481 98412320
1655693292473693610 184738105
1655693292693174854 18758612
1655693292912166600 6246312
1655693293125040672 8976209
1655693293344445995 5823819
Process StressGenerator-16:
Traceback (most recent call last):
  File "/usr/local/lib/python3.7/site-packages/urllib3/connectionpool.py", line 710, in urlopen
    chunked=chunked,
  File "/usr/local/lib/python3.7/site-packages/urllib3/connectionpool.py", line 449, in _make_request
    six.raise_from(e, None)
  File "<string>", line 3, in raise_from
  File "/usr/local/lib/python3.7/site-packages/urllib3/connectionpool.py", line 444, in _make_request
    httplib_response = conn.getresponse()
  File "/usr/local/lib/python3.7/http/client.py", line 1321, in getresponse
    response.begin()
  File "/usr/local/lib/python3.7/http/client.py", line 296, in begin
    version, status, reason = self._read_status()
  File "/usr/local/lib/python3.7/http/client.py", line 257, in _read_status
    line = str(self.fp.readline(_MAXLINE + 1), "iso-8859-1")
  File "/usr/local/lib/python3.7/socket.py", line 589, in readinto
    return self._sock.recv_into(b)
ConnectionResetError: [Errno 104] Connection reset by peer

During handling of the above exception, another exception occurred:

Traceback (most recent call last):
  File "/usr/local/lib/python3.7/site-packages/requests/adapters.py", line 499, in send
    timeout=timeout,
  File "/usr/local/lib/python3.7/site-packages/urllib3/connectionpool.py", line 786, in urlopen
    method, url, error=e, _pool=self, _stacktrace=sys.exc_info()[2]
  File "/usr/local/lib/python3.7/site-packages/urllib3/util/retry.py", line 550, in increment
    raise six.reraise(type(error), error, _stacktrace)
  File "/usr/local/lib/python3.7/site-packages/urllib3/packages/six.py", line 769, in reraise
    raise value.with_traceback(tb)
  File "/usr/local/lib/python3.7/site-packages/urllib3/connectionpool.py", line 710, in urlopen
    chunked=chunked,
  File "/usr/local/lib/python3.7/site-packages/urllib3/connectionpool.py", line 449, in _make_request
    six.raise_from(e, None)
  File "<string>", line 3, in raise_from
  File "/usr/local/lib/python3.7/site-packages/urllib3/connectionpool.py", line 444, in _make_request
    httplib_response = conn.getresponse()
  File "/usr/local/lib/python3.7/http/client.py", line 1321, in getresponse
    response.begin()
  File "/usr/local/lib/python3.7/http/client.py", line 296, in begin
    version, status, reason = self._read_status()
  File "/usr/local/lib/python3.7/http/client.py", line 257, in _read_status
    line = str(self.fp.readline(_MAXLINE + 1), "iso-8859-1")
  File "/usr/local/lib/python3.7/socket.py", line 589, in readinto
    return self._sock.recv_into(b)
urllib3.exceptions.ProtocolError: ('Connection aborted.', ConnectionResetError(104, 'Connection reset by peer'))

During handling of the above exception, another exception occurred:

Traceback (most recent call last):
  File "/usr/local/lib/python3.7/multiprocessing/process.py", line 297, in _bootstrap
    self.run()
  File "app.py", line 43, in run
    self._write_work()
  File "app.py", line 54, in _write_work
    self.do_post_request.perform(encode_bytes_as_base64)
  File "/app/models/simple_http_log_client.py", line 11, in perform
    return self._simple_requests_scenario(body_json_content)
  File "/app/models/simple_http_log_client.py", line 16, in _simple_requests_scenario
    return self.session.post(f"{self.api_url}/insert", body_json_content)
  File "/usr/local/lib/python3.7/site-packages/requests/sessions.py", line 635, in post
    return self.request("POST", url, data=data, json=json, **kwargs)
  File "/usr/local/lib/python3.7/site-packages/requests/sessions.py", line 587, in request
    resp = self.send(prep, **send_kwargs)
  File "/usr/local/lib/python3.7/site-packages/requests/sessions.py", line 701, in send
    r = adapter.send(request, **kwargs)
  File "/usr/local/lib/python3.7/site-packages/requests/adapters.py", line 547, in send
    raise ConnectionError(err, request=request)
requests.exceptions.ConnectionError: ('Connection aborted.', ConnectionResetError(104, 'Connection reset by peer'))
1655693294576606798 1025675167
1655693294792263442 6411400
1655693295082638432 88096940
1655693295293826098 8501885
1655693295595579148 97933748
1655693295810601907 11908918
1655693296069311439 54967823
1655693296274620351 4632790
1655693296481409870 3676534
1655693296692652220 8723005
1655693296977858589 83780854
1655693297200713886 19288704
1655693297405784301 2962871
1655693297678344461 10593246
1655693297895182752 15251837
1655693298177053540 9305416
1655693298396184689 11435630
1655693298610674664 14202782
1655693298836447903 25092261
1655693299082932609 14707278
1655693299374735675 90796018
1655693299584979772 4842517
1655693299794396756 4457734
1655693300086074365 90148069
1655693300376786030 72337640
1655693300590262593 11300827
1655693300800029176 4691160
1655693301084434576 79112364
1655693301292537106 7455171
1655693301575515080 66368948
1655693301792968595 13905370
1655693302078625484 8506915
1655693302291447991 9895881
1655693302496989439 4429094
1655693302787576286 10531074
1655693304113552989 1114221639
1655693304324997396 9106377
1655693304529559855 4380736
1655693304776719868 5644412
1655693304987867280 5595950
1655693305200740859 9257714
1655693305472490033 3648398
1655693305687740819 8526119
1655693305974914255 75211448
1655693306185977296 6780874
1655693306397754904 4930194
1655693306607355952 8413104
1655693306820950209 7135058
1655693307025352877 4093284
1655693307280998461 52977129
1655693307488162776 3243440
1655693307785866108 82863273
1655693308197865082 206122131
1655693308491854652 88941161
1655693308702625011 9692175
1655693308970278007 65555336
