1655403027586660286 0
1655403028587882804 0
1655403029589049814 0
1655403030590198813 0
1655403031590357504 0
1655403032591505857 0
1655403033592660059 0
1655403034593830336 0
1655403035594961139 0
1655403036596146684 2
1655403037597245188 44
----------------------------------------
Exception happened during processing of request from ('10.244.7.14', 47786)
Traceback (most recent call last):
  File "/usr/local/lib/python3.7/socketserver.py", line 316, in _handle_request_noblock
    self.process_request(request, client_address)
  File "/usr/local/lib/python3.7/socketserver.py", line 347, in process_request
    self.finish_request(request, client_address)
  File "/usr/local/lib/python3.7/socketserver.py", line 360, in finish_request
    self.RequestHandlerClass(request, client_address, self)
  File "/app/models/http_disk_log_app.py", line 17, in __init__
    super().__init__(request, client_address, server)
  File "/usr/local/lib/python3.7/socketserver.py", line 720, in __init__
    self.handle()
  File "/usr/local/lib/python3.7/http/server.py", line 426, in handle
    self.handle_one_request()
  File "/usr/local/lib/python3.7/http/server.py", line 414, in handle_one_request
    method()
  File "/app/models/http_disk_log_app.py", line 43, in do_GET
    self.wfile.write(bytes(json.dumps(server_response), 'utf-8'))
  File "/usr/local/lib/python3.7/socketserver.py", line 799, in write
    self._sock.sendall(b)
BrokenPipeError: [Errno 32] Broken pipe
----------------------------------------
----------------------------------------
Exception happened during processing of request from ('10.244.2.11', 32896)
Traceback (most recent call last):
  File "/usr/local/lib/python3.7/socketserver.py", line 316, in _handle_request_noblock
    self.process_request(request, client_address)
  File "/usr/local/lib/python3.7/socketserver.py", line 347, in process_request
    self.finish_request(request, client_address)
  File "/usr/local/lib/python3.7/socketserver.py", line 360, in finish_request
    self.RequestHandlerClass(request, client_address, self)
  File "/app/models/http_disk_log_app.py", line 17, in __init__
    super().__init__(request, client_address, server)
  File "/usr/local/lib/python3.7/socketserver.py", line 720, in __init__
    self.handle()
  File "/usr/local/lib/python3.7/http/server.py", line 426, in handle
    self.handle_one_request()
  File "/usr/local/lib/python3.7/http/server.py", line 414, in handle_one_request
    method()
  File "/app/models/http_disk_log_app.py", line 43, in do_GET
    self.wfile.write(bytes(json.dumps(server_response), 'utf-8'))
  File "/usr/local/lib/python3.7/socketserver.py", line 799, in write
    self._sock.sendall(b)
BrokenPipeError: [Errno 32] Broken pipe
----------------------------------------
----------------------------------------
Exception happened during processing of request from ('10.244.2.11', 32898)
Traceback (most recent call last):
  File "/usr/local/lib/python3.7/socketserver.py", line 316, in _handle_request_noblock
    self.process_request(request, client_address)
  File "/usr/local/lib/python3.7/socketserver.py", line 347, in process_request
    self.finish_request(request, client_address)
  File "/usr/local/lib/python3.7/socketserver.py", line 360, in finish_request
    self.RequestHandlerClass(request, client_address, self)
  File "/app/models/http_disk_log_app.py", line 17, in __init__
    super().__init__(request, client_address, server)
  File "/usr/local/lib/python3.7/socketserver.py", line 720, in __init__
    self.handle()
  File "/usr/local/lib/python3.7/http/server.py", line 426, in handle
    self.handle_one_request()
  File "/usr/local/lib/python3.7/http/server.py", line 414, in handle_one_request
    method()
  File "/app/models/http_disk_log_app.py", line 43, in do_GET
    self.wfile.write(bytes(json.dumps(server_response), 'utf-8'))
  File "/usr/local/lib/python3.7/socketserver.py", line 799, in write
    self._sock.sendall(b)
BrokenPipeError: [Errno 32] Broken pipe
----------------------------------------
----------------------------------------
Exception happened during processing of request from ('10.244.7.14', 47766)
Traceback (most recent call last):
  File "/usr/local/lib/python3.7/socketserver.py", line 316, in _handle_request_noblock
    self.process_request(request, client_address)
  File "/usr/local/lib/python3.7/socketserver.py", line 347, in process_request
    self.finish_request(request, client_address)
  File "/usr/local/lib/python3.7/socketserver.py", line 360, in finish_request
    self.RequestHandlerClass(request, client_address, self)
  File "/app/models/http_disk_log_app.py", line 17, in __init__
    super().__init__(request, client_address, server)
  File "/usr/local/lib/python3.7/socketserver.py", line 720, in __init__
    self.handle()
  File "/usr/local/lib/python3.7/http/server.py", line 426, in handle
    self.handle_one_request()
  File "/usr/local/lib/python3.7/http/server.py", line 414, in handle_one_request
    method()
  File "/app/models/http_disk_log_app.py", line 43, in do_GET
    self.wfile.write(bytes(json.dumps(server_response), 'utf-8'))
  File "/usr/local/lib/python3.7/socketserver.py", line 799, in write
    self._sock.sendall(b)
BrokenPipeError: [Errno 32] Broken pipe
----------------------------------------
----------------------------------------
Exception happened during processing of request from ('10.244.7.14', 47764)
Traceback (most recent call last):
  File "/usr/local/lib/python3.7/socketserver.py", line 316, in _handle_request_noblock
    self.process_request(request, client_address)
  File "/usr/local/lib/python3.7/socketserver.py", line 347, in process_request
    self.finish_request(request, client_address)
  File "/usr/local/lib/python3.7/socketserver.py", line 360, in finish_request
    self.RequestHandlerClass(request, client_address, self)
  File "/app/models/http_disk_log_app.py", line 17, in __init__
    super().__init__(request, client_address, server)
  File "/usr/local/lib/python3.7/socketserver.py", line 720, in __init__
    self.handle()
  File "/usr/local/lib/python3.7/http/server.py", line 426, in handle
    self.handle_one_request()
  File "/usr/local/lib/python3.7/http/server.py", line 414, in handle_one_request
    method()
  File "/app/models/http_disk_log_app.py", line 43, in do_GET
    self.wfile.write(bytes(json.dumps(server_response), 'utf-8'))
  File "/usr/local/lib/python3.7/socketserver.py", line 799, in write
    self._sock.sendall(b)
BrokenPipeError: [Errno 32] Broken pipe
----------------------------------------
1655403038598394161 21
1655403039599534930 0
1655403040600677952 0
1655403041601827190 0
1655403042602976181 0
1655403043604129548 0
1655403044605293415 23
1655403045606441190 37
----------------------------------------
Exception happened during processing of request from ('10.244.1.4', 49040)
Traceback (most recent call last):
  File "/usr/local/lib/python3.7/socketserver.py", line 316, in _handle_request_noblock
    self.process_request(request, client_address)
  File "/usr/local/lib/python3.7/socketserver.py", line 347, in process_request
    self.finish_request(request, client_address)
  File "/usr/local/lib/python3.7/socketserver.py", line 360, in finish_request
    self.RequestHandlerClass(request, client_address, self)
  File "/app/models/http_disk_log_app.py", line 17, in __init__
    super().__init__(request, client_address, server)
  File "/usr/local/lib/python3.7/socketserver.py", line 720, in __init__
    self.handle()
  File "/usr/local/lib/python3.7/http/server.py", line 426, in handle
    self.handle_one_request()
  File "/usr/local/lib/python3.7/http/server.py", line 414, in handle_one_request
    method()
  File "/app/models/http_disk_log_app.py", line 43, in do_GET
    self.wfile.write(bytes(json.dumps(server_response), 'utf-8'))
  File "/usr/local/lib/python3.7/socketserver.py", line 799, in write
    self._sock.sendall(b)
BrokenPipeError: [Errno 32] Broken pipe
----------------------------------------
----------------------------------------
Exception happened during processing of request from ('10.244.1.4', 49042)
Traceback (most recent call last):
  File "/usr/local/lib/python3.7/socketserver.py", line 316, in _handle_request_noblock
    self.process_request(request, client_address)
  File "/usr/local/lib/python3.7/socketserver.py", line 347, in process_request
    self.finish_request(request, client_address)
  File "/usr/local/lib/python3.7/socketserver.py", line 360, in finish_request
    self.RequestHandlerClass(request, client_address, self)
  File "/app/models/http_disk_log_app.py", line 17, in __init__
    super().__init__(request, client_address, server)
  File "/usr/local/lib/python3.7/socketserver.py", line 720, in __init__
    self.handle()
  File "/usr/local/lib/python3.7/http/server.py", line 426, in handle
    self.handle_one_request()
  File "/usr/local/lib/python3.7/http/server.py", line 414, in handle_one_request
    method()
  File "/app/models/http_disk_log_app.py", line 43, in do_GET
    self.wfile.write(bytes(json.dumps(server_response), 'utf-8'))
  File "/usr/local/lib/python3.7/socketserver.py", line 799, in write
    self._sock.sendall(b)
BrokenPipeError: [Errno 32] Broken pipe
----------------------------------------
1655403046607594191 30
1655403047608752573 0
1655403048609901659 0
1655403049611041850 0
1655403050612176567 0
1655403051613342439 0
1655403052614367749 10
1655403053615481710 49
----------------------------------------
Exception happened during processing of request from ('10.244.9.9', 37632)
Traceback (most recent call last):
  File "/usr/local/lib/python3.7/socketserver.py", line 316, in _handle_request_noblock
    self.process_request(request, client_address)
  File "/usr/local/lib/python3.7/socketserver.py", line 347, in process_request
    self.finish_request(request, client_address)
  File "/usr/local/lib/python3.7/socketserver.py", line 360, in finish_request
    self.RequestHandlerClass(request, client_address, self)
  File "/app/models/http_disk_log_app.py", line 17, in __init__
    super().__init__(request, client_address, server)
  File "/usr/local/lib/python3.7/socketserver.py", line 720, in __init__
    self.handle()
  File "/usr/local/lib/python3.7/http/server.py", line 426, in handle
    self.handle_one_request()
  File "/usr/local/lib/python3.7/http/server.py", line 414, in handle_one_request
    method()
  File "/app/models/http_disk_log_app.py", line 43, in do_GET
    self.wfile.write(bytes(json.dumps(server_response), 'utf-8'))
  File "/usr/local/lib/python3.7/socketserver.py", line 799, in write
    self._sock.sendall(b)
ConnectionResetError: [Errno 104] Connection reset by peer
----------------------------------------
1655403054616597862 31
1655403055617681356 0
1655403056618844850 0
1655403057620001731 0
1655403058621144630 0
1655403059622287013 0
1655403060623424912 0
1655403061624563071 0
1655403062625696467 0
1655403063626813203 0
1655403064627957537 0
1655403065629101454 0
1655403066630255228 0
1655403067631419192 0
1655403068632566446 0
1655403069633690781 0
1655403070634808032 0
1655403071635970611 0
1655403072637114855 0
1655403073638258600 0
1655403074639423134 0
1655403075640569466 0
1655403076641716285 0
1655403077642367407 0
1655403078643505993 0
1655403079644661348 0
1655403080645809716 0
1655403081646955165 0
1655403082648095375 0
1655403083649209237 0
1655403084650338918 0
1655403085651487573 0
1655403086652604417 0
1655403087653761865 0
1655403088654926111 0
1655403089656088292 0
1655403090657234391 0
1655403091658382250 0
1655403092659474989 0
1655403093660633150 0
1655403094661788198 0
1655403095662903888 0
1655403096664068966 0
1655403097665214815 0
1655403098666359123 0
1655403099667447294 0
1655403100668628121 0
1655403101669765659 0
1655403102670909316 0
1655403103672068066 0
1655403104673229915 0
1655403105674376380 0
1655403106675488255 0
1655403107676633721 0
1655403108677772419 0
1655403109678919254 0
1655403110680060834 0
1655403111681207174 0
1655403112682365415 0
1655403113683516024 0
1655403114684647738 0
1655403115685784266 0
1655403116686942764 0
1655403117688093038 0
1655403118689233086 0
1655403119690376497 0
1655403120691513551 0
1655403121692652440 0
1655403122693797130 0
1655403123694911214 0
1655403124696065533 0
1655403125697204273 0
1655403126698426410 0
