1655694905789932412 181313300
1655694906102033066 98794213
1655694906388919651 62254023
1655694906674150821 72518310
1655694906895704629 5643003
1655694907107758089 5277074
1655694907321247029 6809374
1655694907534331835 8996682
1655694907750114507 12218161
1655694907997751187 7455643
1655694908274215967 49990120
1655694908599685959 99619516
1655694908878420496 48127818
1655694909112696604 15592449
1655694909345259314 17798611
1655694909555701377 6439386
1655694909764341334 5018183
1655694909978614985 10557941
1655694910186736376 4415226
1655694910397186740 7468900
1655694910695940694 90791612
1655694910931831660 17151083
1655694911185340982 8399786
1655694911391154752 3132081
1655694911620750023 20776080
1655694911840608478 9989499
1655694912065382865 19303342
1655694912292526781 11520733
1655694912511059651 14414560
1655694912726628313 11910714
1655694912982106695 4663336
1655694913209256223 22470351
1655694913414848062 3034832
1655694913625976435 7539607
1655694913853504618 12295514
1655694914083984965 18145746
1655694914322055029 34231849
1655694914556684480 16362240
1655694914778531982 15785411
1655694914989629708 5385912
1655694915203138876 5755575
1655694915416794351 6152899
1655694915626098291 3300532
1655694915833689857 3307604
1655694916047579459 6021737
1655694916280829744 4370832
1655694916493613408 4483004
1655694916713701981 10965506
1655694916970397239 51942464
1655694917187585654 10466002
1655694917409096464 7677112
1655694917625955330 5902575
1655694917841657291 4738412
1655694918055050412 5260163
1655694918274759449 13628977
1655694918491272076 5998763
1655694918705058162 10921956
1655694918920299667 7119965
1655694919132296623 7540500
1655694919398803014 21710703
1655694919627727974 13599101
1655694919843677904 11984834
1655694920052694383 4831911
1655694920274349940 17451130
1655694920493689902 14074289
1655694920720696235 11291133
1655694920941543104 8389126
1655694921160553105 10993656
1655694921384979620 9197210
1655694921603416510 5664659
1655694921818703317 5606157
1655694922035852197 13747907
1655694922262726573 6793662
1655694922473592598 6336627
1655694922679333481 3602944
1655694922885700222 3286522
1655694923097920735 8961301
1655694923345409910 31285928
1655694923565920172 17407742
1655694923801614899 19082658
1655694924039946153 18561903
1655694924264495674 8936537
1655694924513742417 23348042
1655694924794703338 16758496
1655694925079405470 67884783
1655694925311765461 27035509
1655694925535703548 10192446
1655694925742176614 3676667
1655694925947802111 3389287
1655694926152820074 3073275
1655694926374708087 15030778
1655694926594294320 6472898
1655694926812406147 11048345
1655694927034716987 15311618
1655694927257655209 9592100
1655694927467291130 5189838
1655694927675978190 4829934
1655694927883520428 3507692
1655694928090460038 3384856
1655694928302089688 5863183
1655694928535276918 8773804
1655694928748035449 3802875
1655694928959553737 4756942
1655694929177663365 10317329
1655694929396629623 10165388
1655694929612678674 8612320
1655694929826249527 7751179
1655694930048567010 8645718
1655694930282469165 10501893
1655694930519384121 10381171
1655694931763086403 1034326174
1655694931980633837 7974026
1655694932201200922 10038126
1655694932420658185 9157507
1655694932631568018 5570600
1655694932845182334 8281380
1655694933059940203 7849991
1655694933288853555 10635326
1655694933510768205 12857916
1655694933753375381 34618366
1655694933986817093 14151674
1655694934269678488 64429455
1655694934498070086 11470758
1655694934722599801 11272184
1655694934946743107 18997010
1655694935164650907 14900084
1655694935374046111 7040508
1655694935670307061 82056631
1655694935896701046 21186412
1655694936115751668 12460305
1655694936325626968 3529006
1655694936531383780 3495770
1655694936772679994 39135180
1655694936981309212 5170479
1655694937188528704 4455689
1655694937401964654 10256153
1655694937616737738 7532508
1655694937829754583 7174972
1655694938042401946 4342659
1655694938254446442 6252132
1655694938479855361 8160880
1655694938700737002 12481631
1655694938916930263 12828161
1655694939128376696 4472996
1655694939340479423 9117818
1655694939583860894 11506548
1655694939793019345 3668409
1655694940000457512 3810020
1655694940208792848 4475126
1655694940481276535 65465250
1655694940791546463 93848446
1655694941088736815 71109701
1655694941386793283 70457079
1655694941706680545 87597729
1655694941974842143 62489106
Process StressGeneratorLogger-1:
Process StressGenerator-4:
Traceback (most recent call last):
  File "/usr/local/lib/python3.7/site-packages/urllib3/connectionpool.py", line 710, in urlopen
    chunked=chunked,
  File "/usr/local/lib/python3.7/site-packages/urllib3/connectionpool.py", line 449, in _make_request
    six.raise_from(e, None)
  File "<string>", line 3, in raise_from
  File "/usr/local/lib/python3.7/site-packages/urllib3/connectionpool.py", line 444, in _make_request
    httplib_response = conn.getresponse()
  File "/usr/local/lib/python3.7/http/client.py", line 1321, in getresponse
    response.begin()
  File "/usr/local/lib/python3.7/http/client.py", line 296, in begin
    version, status, reason = self._read_status()
  File "/usr/local/lib/python3.7/http/client.py", line 257, in _read_status
    line = str(self.fp.readline(_MAXLINE + 1), "iso-8859-1")
  File "/usr/local/lib/python3.7/socket.py", line 589, in readinto
    return self._sock.recv_into(b)
ConnectionResetError: [Errno 104] Connection reset by peer

During handling of the above exception, another exception occurred:

Traceback (most recent call last):
  File "/usr/local/lib/python3.7/site-packages/requests/adapters.py", line 499, in send
    timeout=timeout,
  File "/usr/local/lib/python3.7/site-packages/urllib3/connectionpool.py", line 786, in urlopen
    method, url, error=e, _pool=self, _stacktrace=sys.exc_info()[2]
  File "/usr/local/lib/python3.7/site-packages/urllib3/util/retry.py", line 550, in increment
    raise six.reraise(type(error), error, _stacktrace)
  File "/usr/local/lib/python3.7/site-packages/urllib3/packages/six.py", line 769, in reraise
    raise value.with_traceback(tb)
  File "/usr/local/lib/python3.7/site-packages/urllib3/connectionpool.py", line 710, in urlopen
    chunked=chunked,
  File "/usr/local/lib/python3.7/site-packages/urllib3/connectionpool.py", line 449, in _make_request
    six.raise_from(e, None)
  File "<string>", line 3, in raise_from
  File "/usr/local/lib/python3.7/site-packages/urllib3/connectionpool.py", line 444, in _make_request
    httplib_response = conn.getresponse()
  File "/usr/local/lib/python3.7/http/client.py", line 1321, in getresponse
    response.begin()
  File "/usr/local/lib/python3.7/http/client.py", line 296, in begin
    version, status, reason = self._read_status()
  File "/usr/local/lib/python3.7/http/client.py", line 257, in _read_status
    line = str(self.fp.readline(_MAXLINE + 1), "iso-8859-1")
  File "/usr/local/lib/python3.7/socket.py", line 589, in readinto
    return self._sock.recv_into(b)
urllib3.exceptions.ProtocolError: ('Connection aborted.', ConnectionResetError(104, 'Connection reset by peer'))

During handling of the above exception, another exception occurred:

Traceback (most recent call last):
  File "/usr/local/lib/python3.7/multiprocessing/process.py", line 297, in _bootstrap
    self.run()
  File "app.py", line 43, in run
    self._write_work()
  File "app.py", line 54, in _write_work
    self.do_post_request.perform(encode_bytes_as_base64)
  File "/app/models/simple_http_log_client.py", line 11, in perform
    return self._simple_requests_scenario(body_json_content)
  File "/app/models/simple_http_log_client.py", line 16, in _simple_requests_scenario
    return self.session.post(f"{self.api_url}/insert", body_json_content)
  File "/usr/local/lib/python3.7/site-packages/requests/sessions.py", line 635, in post
    return self.request("POST", url, data=data, json=json, **kwargs)
  File "/usr/local/lib/python3.7/site-packages/requests/sessions.py", line 587, in request
    resp = self.send(prep, **send_kwargs)
  File "/usr/local/lib/python3.7/site-packages/requests/sessions.py", line 701, in send
    r = adapter.send(request, **kwargs)
  File "/usr/local/lib/python3.7/site-packages/requests/adapters.py", line 547, in send
    raise ConnectionError(err, request=request)
requests.exceptions.ConnectionError: ('Connection aborted.', ConnectionResetError(104, 'Connection reset by peer'))
Traceback (most recent call last):
  File "/usr/local/lib/python3.7/site-packages/urllib3/connectionpool.py", line 710, in urlopen
    chunked=chunked,
  File "/usr/local/lib/python3.7/site-packages/urllib3/connectionpool.py", line 449, in _make_request
    six.raise_from(e, None)
  File "<string>", line 3, in raise_from
  File "/usr/local/lib/python3.7/site-packages/urllib3/connectionpool.py", line 444, in _make_request
    httplib_response = conn.getresponse()
  File "/usr/local/lib/python3.7/http/client.py", line 1321, in getresponse
    response.begin()
  File "/usr/local/lib/python3.7/http/client.py", line 296, in begin
    version, status, reason = self._read_status()
  File "/usr/local/lib/python3.7/http/client.py", line 257, in _read_status
    line = str(self.fp.readline(_MAXLINE + 1), "iso-8859-1")
  File "/usr/local/lib/python3.7/socket.py", line 589, in readinto
    return self._sock.recv_into(b)
ConnectionResetError: [Errno 104] Connection reset by peer

During handling of the above exception, another exception occurred:

Traceback (most recent call last):
  File "/usr/local/lib/python3.7/site-packages/requests/adapters.py", line 499, in send
    timeout=timeout,
  File "/usr/local/lib/python3.7/site-packages/urllib3/connectionpool.py", line 786, in urlopen
    method, url, error=e, _pool=self, _stacktrace=sys.exc_info()[2]
  File "/usr/local/lib/python3.7/site-packages/urllib3/util/retry.py", line 550, in increment
    raise six.reraise(type(error), error, _stacktrace)
  File "/usr/local/lib/python3.7/site-packages/urllib3/packages/six.py", line 769, in reraise
    raise value.with_traceback(tb)
  File "/usr/local/lib/python3.7/site-packages/urllib3/connectionpool.py", line 710, in urlopen
    chunked=chunked,
  File "/usr/local/lib/python3.7/site-packages/urllib3/connectionpool.py", line 449, in _make_request
    six.raise_from(e, None)
  File "<string>", line 3, in raise_from
  File "/usr/local/lib/python3.7/site-packages/urllib3/connectionpool.py", line 444, in _make_request
    httplib_response = conn.getresponse()
  File "/usr/local/lib/python3.7/http/client.py", line 1321, in getresponse
    response.begin()
  File "/usr/local/lib/python3.7/http/client.py", line 296, in begin
    version, status, reason = self._read_status()
  File "/usr/local/lib/python3.7/http/client.py", line 257, in _read_status
    line = str(self.fp.readline(_MAXLINE + 1), "iso-8859-1")
  File "/usr/local/lib/python3.7/socket.py", line 589, in readinto
    return self._sock.recv_into(b)
urllib3.exceptions.ProtocolError: ('Connection aborted.', ConnectionResetError(104, 'Connection reset by peer'))

During handling of the above exception, another exception occurred:

Traceback (most recent call last):
  File "/usr/local/lib/python3.7/multiprocessing/process.py", line 297, in _bootstrap
    self.run()
  File "app.py", line 43, in run
    self._write_work()
  File "app.py", line 74, in _write_work
    self._calculate_latency(self.do_post_request, encode_bytes_as_base64)
  File "app.py", line 81, in _calculate_latency
    client.perform(content)
  File "/app/models/simple_http_log_client.py", line 11, in perform
    return self._simple_requests_scenario(body_json_content)
  File "/app/models/simple_http_log_client.py", line 16, in _simple_requests_scenario
    return self.session.post(f"{self.api_url}/insert", body_json_content)
  File "/usr/local/lib/python3.7/site-packages/requests/sessions.py", line 635, in post
    return self.request("POST", url, data=data, json=json, **kwargs)
  File "/usr/local/lib/python3.7/site-packages/requests/sessions.py", line 587, in request
    resp = self.send(prep, **send_kwargs)
  File "/usr/local/lib/python3.7/site-packages/requests/sessions.py", line 701, in send
    r = adapter.send(request, **kwargs)
  File "/usr/local/lib/python3.7/site-packages/requests/adapters.py", line 547, in send
    raise ConnectionError(err, request=request)
requests.exceptions.ConnectionError: ('Connection aborted.', ConnectionResetError(104, 'Connection reset by peer'))
