1654498762960500828 786063853
1654498764030483841 799304521
1654498767724841588 503370343
1654498770133574732 616051759
1654498774251561133 355975241
1654498786061408242 412248879
1654498793212115415 2049757377
1654498797029780363 495056337
1654498801495710199 549980055
1654498805024224612 1280815662
1654498808741372449 388091092
1654498813341583161 1327949809
1654498830201370531 15889628120
1654498833001403225 476673655
1654498834137409879 710179521
1654498837569017708 1760331921
1654498838729213330 129920012
1654498840922187700 1964540304
1654498843531609403 1486071606
1654498844460576007 903389952
1654498848846219305 4002800624
1654498849450432852 481374953
1654498856409631694 4379128966
1654498860824393225 1928795699
1654498861557170985 629406134
1654498862316747544 759222990
1654498867621842200 1605361191
1654498871194621900 371064124
1654498882523174812 7765477445
1654498884570702742 1814130444
1654498887250374961 913771078
1654498888645169620 1393652141
1654498891506076348 1612395024
1654498892613635095 991333096
1654498893562721396 948538895
1654498897931202890 815865172
1654498898715441421 680893547
1654498900036766070 1032173012
1654498901818106101 1780479127
Exception in thread 18:
Traceback (most recent call last):
  File "/usr/local/lib/python3.7/site-packages/urllib3/connection.py", line 175, in _new_conn
    (self._dns_host, self.port), self.timeout, **extra_kw
  File "/usr/local/lib/python3.7/site-packages/urllib3/util/connection.py", line 95, in create_connection
    raise err
  File "/usr/local/lib/python3.7/site-packages/urllib3/util/connection.py", line 85, in create_connection
    sock.connect(sa)
TimeoutError: [Errno 110] Connection timed out

During handling of the above exception, another exception occurred:

Traceback (most recent call last):
  File "/usr/local/lib/python3.7/site-packages/urllib3/connectionpool.py", line 710, in urlopen
    chunked=chunked,
  File "/usr/local/lib/python3.7/site-packages/urllib3/connectionpool.py", line 398, in _make_request
    conn.request(method, url, **httplib_request_kw)
  File "/usr/local/lib/python3.7/site-packages/urllib3/connection.py", line 239, in request
    super(HTTPConnection, self).request(method, url, body=body, headers=headers)
  File "/usr/local/lib/python3.7/http/client.py", line 1229, in request
    self._send_request(method, url, body, headers, encode_chunked)
  File "/usr/local/lib/python3.7/http/client.py", line 1275, in _send_request
    self.endheaders(body, encode_chunked=encode_chunked)
  File "/usr/local/lib/python3.7/http/client.py", line 1224, in endheaders
    self._send_output(message_body, encode_chunked=encode_chunked)
  File "/usr/local/lib/python3.7/http/client.py", line 1016, in _send_output
    self.send(msg)
  File "/usr/local/lib/python3.7/http/client.py", line 956, in send
    self.connect()
  File "/usr/local/lib/python3.7/site-packages/urllib3/connection.py", line 205, in connect
    conn = self._new_conn()
  File "/usr/local/lib/python3.7/site-packages/urllib3/connection.py", line 187, in _new_conn
    self, "Failed to establish a new connection: %s" % e
urllib3.exceptions.NewConnectionError: <urllib3.connection.HTTPConnection object at 0x7f1ef1cd7eb8>: Failed to establish a new connection: [Errno 110] Connection timed out

During handling of the above exception, another exception occurred:

Traceback (most recent call last):
  File "/usr/local/lib/python3.7/site-packages/requests/adapters.py", line 450, in send
    timeout=timeout
  File "/usr/local/lib/python3.7/site-packages/urllib3/connectionpool.py", line 786, in urlopen
    method, url, error=e, _pool=self, _stacktrace=sys.exc_info()[2]
  File "/usr/local/lib/python3.7/site-packages/urllib3/util/retry.py", line 592, in increment
    raise MaxRetryError(_pool, url, error or ResponseError(cause))
urllib3.exceptions.MaxRetryError: HTTPConnectionPool(host='http-log-server', port=8001): Max retries exceeded with url: /db (Caused by NewConnectionError('<urllib3.connection.HTTPConnection object at 0x7f1ef1cd7eb8>: Failed to establish a new connection: [Errno 110] Connection timed out'))

During handling of the above exception, another exception occurred:

Traceback (most recent call last):
  File "/usr/local/lib/python3.7/threading.py", line 917, in _bootstrap_inner
    self.run()
  File "/usr/local/lib/python3.7/threading.py", line 865, in run
    self._target(*self._args, **self._kwargs)
  File "app.py", line 48, in _kubernetes_job
    _write_work(**kwargs)
  File "app.py", line 67, in _write_work
    simple_http_client_post.perform(gibberish_content)
  File "/app/models/simple_http_log_client.py", line 12, in perform
    return self._simple_requests_scenario(body_json_content)
  File "/app/models/simple_http_log_client.py", line 17, in _simple_requests_scenario
    return self.session.post(f"{self.api_url}/db", json=body_json_content)
  File "/usr/local/lib/python3.7/site-packages/requests/sessions.py", line 577, in post
    return self.request('POST', url, data=data, json=json, **kwargs)
  File "/usr/local/lib/python3.7/site-packages/requests/sessions.py", line 529, in request
    resp = self.send(prep, **send_kwargs)
  File "/usr/local/lib/python3.7/site-packages/requests/sessions.py", line 645, in send
    r = adapter.send(request, **kwargs)
  File "/usr/local/lib/python3.7/site-packages/requests/adapters.py", line 519, in send
    raise ConnectionError(e, request=request)
requests.exceptions.ConnectionError: HTTPConnectionPool(host='http-log-server', port=8001): Max retries exceeded with url: /db (Caused by NewConnectionError('<urllib3.connection.HTTPConnection object at 0x7f1ef1cd7eb8>: Failed to establish a new connection: [Errno 110] Connection timed out'))

1654498937821161794 33475175094
1654498943597748207 822939840
1654498948845897113 1579988386
1654498949608219584 567931455
1654498954328668805 932140683
1654498955797084506 1456711787
1654498966601306094 787850040
1654498967509406946 484031460
1654498968503890179 994163147
1654498974502959660 2471363828
1654498979098461973 788496642
1654498981515906847 1379493118
1654498982615318859 1093568383
1654498989037373141 1266877244
1654498993103878899 350303417
1654498997775145667 4655806749
1654499003645922297 1847861921
1654499010111621913 3211839647
1654499013792074257 3679621338
1654499018257570119 1006465923
1654499026596864856 2255750933
1654499035834344449 2793936738
1654499038902431615 271260367
Exception in thread 14:
Traceback (most recent call last):
  File "/usr/local/lib/python3.7/site-packages/urllib3/connection.py", line 175, in _new_conn
    (self._dns_host, self.port), self.timeout, **extra_kw
  File "/usr/local/lib/python3.7/site-packages/urllib3/util/connection.py", line 95, in create_connection
    raise err
  File "/usr/local/lib/python3.7/site-packages/urllib3/util/connection.py", line 85, in create_connection
    sock.connect(sa)
TimeoutError: [Errno 110] Connection timed out

During handling of the above exception, another exception occurred:

Traceback (most recent call last):
  File "/usr/local/lib/python3.7/site-packages/urllib3/connectionpool.py", line 710, in urlopen
    chunked=chunked,
  File "/usr/local/lib/python3.7/site-packages/urllib3/connectionpool.py", line 398, in _make_request
    conn.request(method, url, **httplib_request_kw)
  File "/usr/local/lib/python3.7/site-packages/urllib3/connection.py", line 239, in request
    super(HTTPConnection, self).request(method, url, body=body, headers=headers)
  File "/usr/local/lib/python3.7/http/client.py", line 1229, in request
    self._send_request(method, url, body, headers, encode_chunked)
  File "/usr/local/lib/python3.7/http/client.py", line 1275, in _send_request
    self.endheaders(body, encode_chunked=encode_chunked)
  File "/usr/local/lib/python3.7/http/client.py", line 1224, in endheaders
    self._send_output(message_body, encode_chunked=encode_chunked)
  File "/usr/local/lib/python3.7/http/client.py", line 1016, in _send_output
    self.send(msg)
  File "/usr/local/lib/python3.7/http/client.py", line 956, in send
    self.connect()
  File "/usr/local/lib/python3.7/site-packages/urllib3/connection.py", line 205, in connect
    conn = self._new_conn()
  File "/usr/local/lib/python3.7/site-packages/urllib3/connection.py", line 187, in _new_conn
    self, "Failed to establish a new connection: %s" % e
urllib3.exceptions.NewConnectionError: <urllib3.connection.HTTPConnection object at 0x7f1ee02b5940>: Failed to establish a new connection: [Errno 110] Connection timed out

During handling of the above exception, another exception occurred:

Traceback (most recent call last):
  File "/usr/local/lib/python3.7/site-packages/requests/adapters.py", line 450, in send
    timeout=timeout
  File "/usr/local/lib/python3.7/site-packages/urllib3/connectionpool.py", line 786, in urlopen
    method, url, error=e, _pool=self, _stacktrace=sys.exc_info()[2]
  File "/usr/local/lib/python3.7/site-packages/urllib3/util/retry.py", line 592, in increment
    raise MaxRetryError(_pool, url, error or ResponseError(cause))
urllib3.exceptions.MaxRetryError: HTTPConnectionPool(host='http-log-server', port=8001): Max retries exceeded with url: /db (Caused by NewConnectionError('<urllib3.connection.HTTPConnection object at 0x7f1ee02b5940>: Failed to establish a new connection: [Errno 110] Connection timed out'))

During handling of the above exception, another exception occurred:

Traceback (most recent call last):
  File "/usr/local/lib/python3.7/threading.py", line 917, in _bootstrap_inner
    self.run()
  File "/usr/local/lib/python3.7/threading.py", line 865, in run
    self._target(*self._args, **self._kwargs)
  File "app.py", line 48, in _kubernetes_job
    _write_work(**kwargs)
  File "app.py", line 67, in _write_work
    simple_http_client_post.perform(gibberish_content)
  File "/app/models/simple_http_log_client.py", line 12, in perform
    return self._simple_requests_scenario(body_json_content)
  File "/app/models/simple_http_log_client.py", line 17, in _simple_requests_scenario
    return self.session.post(f"{self.api_url}/db", json=body_json_content)
  File "/usr/local/lib/python3.7/site-packages/requests/sessions.py", line 577, in post
    return self.request('POST', url, data=data, json=json, **kwargs)
  File "/usr/local/lib/python3.7/site-packages/requests/sessions.py", line 529, in request
    resp = self.send(prep, **send_kwargs)
  File "/usr/local/lib/python3.7/site-packages/requests/sessions.py", line 645, in send
    r = adapter.send(request, **kwargs)
  File "/usr/local/lib/python3.7/site-packages/requests/adapters.py", line 519, in send
    raise ConnectionError(e, request=request)
requests.exceptions.ConnectionError: HTTPConnectionPool(host='http-log-server', port=8001): Max retries exceeded with url: /db (Caused by NewConnectionError('<urllib3.connection.HTTPConnection object at 0x7f1ee02b5940>: Failed to establish a new connection: [Errno 110] Connection timed out'))

Exception in thread 22:
Traceback (most recent call last):
  File "/usr/local/lib/python3.7/site-packages/urllib3/connection.py", line 175, in _new_conn
    (self._dns_host, self.port), self.timeout, **extra_kw
  File "/usr/local/lib/python3.7/site-packages/urllib3/util/connection.py", line 95, in create_connection
    raise err
  File "/usr/local/lib/python3.7/site-packages/urllib3/util/connection.py", line 85, in create_connection
    sock.connect(sa)
TimeoutError: [Errno 110] Connection timed out

During handling of the above exception, another exception occurred:

Traceback (most recent call last):
  File "/usr/local/lib/python3.7/site-packages/urllib3/connectionpool.py", line 710, in urlopen
    chunked=chunked,
  File "/usr/local/lib/python3.7/site-packages/urllib3/connectionpool.py", line 398, in _make_request
    conn.request(method, url, **httplib_request_kw)
  File "/usr/local/lib/python3.7/site-packages/urllib3/connection.py", line 239, in request
    super(HTTPConnection, self).request(method, url, body=body, headers=headers)
  File "/usr/local/lib/python3.7/http/client.py", line 1229, in request
    self._send_request(method, url, body, headers, encode_chunked)
  File "/usr/local/lib/python3.7/http/client.py", line 1275, in _send_request
    self.endheaders(body, encode_chunked=encode_chunked)
  File "/usr/local/lib/python3.7/http/client.py", line 1224, in endheaders
    self._send_output(message_body, encode_chunked=encode_chunked)
  File "/usr/local/lib/python3.7/http/client.py", line 1016, in _send_output
    self.send(msg)
  File "/usr/local/lib/python3.7/http/client.py", line 956, in send
    self.connect()
  File "/usr/local/lib/python3.7/site-packages/urllib3/connection.py", line 205, in connect
    conn = self._new_conn()
  File "/usr/local/lib/python3.7/site-packages/urllib3/connection.py", line 187, in _new_conn
    self, "Failed to establish a new connection: %s" % e
urllib3.exceptions.NewConnectionError: <urllib3.connection.HTTPConnection object at 0x7f1ef1c8fd68>: Failed to establish a new connection: [Errno 110] Connection timed out

During handling of the above exception, another exception occurred:

Traceback (most recent call last):
  File "/usr/local/lib/python3.7/site-packages/requests/adapters.py", line 450, in send
    timeout=timeout
  File "/usr/local/lib/python3.7/site-packages/urllib3/connectionpool.py", line 786, in urlopen
    method, url, error=e, _pool=self, _stacktrace=sys.exc_info()[2]
  File "/usr/local/lib/python3.7/site-packages/urllib3/util/retry.py", line 592, in increment
    raise MaxRetryError(_pool, url, error or ResponseError(cause))
urllib3.exceptions.MaxRetryError: HTTPConnectionPool(host='http-log-server', port=8001): Max retries exceeded with url: /db (Caused by NewConnectionError('<urllib3.connection.HTTPConnection object at 0x7f1ef1c8fd68>: Failed to establish a new connection: [Errno 110] Connection timed out'))

During handling of the above exception, another exception occurred:

Traceback (most recent call last):
  File "/usr/local/lib/python3.7/threading.py", line 917, in _bootstrap_inner
    self.run()
  File "/usr/local/lib/python3.7/threading.py", line 865, in run
    self._target(*self._args, **self._kwargs)
  File "app.py", line 48, in _kubernetes_job
    _write_work(**kwargs)
  File "app.py", line 67, in _write_work
    simple_http_client_post.perform(gibberish_content)
  File "/app/models/simple_http_log_client.py", line 12, in perform
    return self._simple_requests_scenario(body_json_content)
  File "/app/models/simple_http_log_client.py", line 17, in _simple_requests_scenario
    return self.session.post(f"{self.api_url}/db", json=body_json_content)
  File "/usr/local/lib/python3.7/site-packages/requests/sessions.py", line 577, in post
    return self.request('POST', url, data=data, json=json, **kwargs)
  File "/usr/local/lib/python3.7/site-packages/requests/sessions.py", line 529, in request
    resp = self.send(prep, **send_kwargs)
  File "/usr/local/lib/python3.7/site-packages/requests/sessions.py", line 645, in send
    r = adapter.send(request, **kwargs)
  File "/usr/local/lib/python3.7/site-packages/requests/adapters.py", line 519, in send
    raise ConnectionError(e, request=request)
requests.exceptions.ConnectionError: HTTPConnectionPool(host='http-log-server', port=8001): Max retries exceeded with url: /db (Caused by NewConnectionError('<urllib3.connection.HTTPConnection object at 0x7f1ef1c8fd68>: Failed to establish a new connection: [Errno 110] Connection timed out'))

1654499040098924796 1095592928
1654499041807325260 1674733455
1654499043151282960 1311522904
1654499047599174761 826052035
1654499050609350860 3009619910
