1654669360584536683 1867348
1654669361394832790 1020722
1654669361738974825 1305303
Exception in thread 3:
Traceback (most recent call last):
  File "/usr/local/lib/python3.7/site-packages/urllib3/connectionpool.py", line 710, in urlopen
    chunked=chunked,
  File "/usr/local/lib/python3.7/site-packages/urllib3/connectionpool.py", line 449, in _make_request
    six.raise_from(e, None)
  File "<string>", line 3, in raise_from
  File "/usr/local/lib/python3.7/site-packages/urllib3/connectionpool.py", line 444, in _make_request
    httplib_response = conn.getresponse()
  File "/usr/local/lib/python3.7/http/client.py", line 1321, in getresponse
    response.begin()
  File "/usr/local/lib/python3.7/http/client.py", line 296, in begin
    version, status, reason = self._read_status()
  File "/usr/local/lib/python3.7/http/client.py", line 257, in _read_status
    line = str(self.fp.readline(_MAXLINE + 1), "iso-8859-1")
  File "/usr/local/lib/python3.7/socket.py", line 589, in readinto
    return self._sock.recv_into(b)
ConnectionResetError: [Errno 104] Connection reset by peer

During handling of the above exception, another exception occurred:

Traceback (most recent call last):
  File "/usr/local/lib/python3.7/site-packages/requests/adapters.py", line 450, in send
    timeout=timeout
  File "/usr/local/lib/python3.7/site-packages/urllib3/connectionpool.py", line 786, in urlopen
    method, url, error=e, _pool=self, _stacktrace=sys.exc_info()[2]
  File "/usr/local/lib/python3.7/site-packages/urllib3/util/retry.py", line 550, in increment
    raise six.reraise(type(error), error, _stacktrace)
  File "/usr/local/lib/python3.7/site-packages/urllib3/packages/six.py", line 769, in reraise
    raise value.with_traceback(tb)
  File "/usr/local/lib/python3.7/site-packages/urllib3/connectionpool.py", line 710, in urlopen
    chunked=chunked,
  File "/usr/local/lib/python3.7/site-packages/urllib3/connectionpool.py", line 449, in _make_request
    six.raise_from(e, None)
  File "<string>", line 3, in raise_from
  File "/usr/local/lib/python3.7/site-packages/urllib3/connectionpool.py", line 444, in _make_request
    httplib_response = conn.getresponse()
  File "/usr/local/lib/python3.7/http/client.py", line 1321, in getresponse
    response.begin()
  File "/usr/local/lib/python3.7/http/client.py", line 296, in begin
    version, status, reason = self._read_status()
  File "/usr/local/lib/python3.7/http/client.py", line 257, in _read_status
    line = str(self.fp.readline(_MAXLINE + 1), "iso-8859-1")
  File "/usr/local/lib/python3.7/socket.py", line 589, in readinto
    return self._sock.recv_into(b)
urllib3.exceptions.ProtocolError: ('Connection aborted.', ConnectionResetError(104, 'Connection reset by peer'))

During handling of the above exception, another exception occurred:

Traceback (most recent call last):
  File "/usr/local/lib/python3.7/threading.py", line 917, in _bootstrap_inner
    self.run()
  File "/usr/local/lib/python3.7/threading.py", line 865, in run
    self._target(*self._args, **self._kwargs)
  File "/app/models/stress_generator.py", line 41, in _kubernetes_job
    self._write_work(**kwargs)
  File "/app/models/stress_generator.py", line 65, in _write_work
    simple_http_client_post.perform(gibberish_content)
  File "/app/models/simple_http_log_client.py", line 12, in perform
    return self._simple_requests_scenario(body_json_content)
  File "/app/models/simple_http_log_client.py", line 17, in _simple_requests_scenario
    return self.session.post(f"{self.api_url}/db", json=body_json_content)
  File "/usr/local/lib/python3.7/site-packages/requests/sessions.py", line 577, in post
    return self.request('POST', url, data=data, json=json, **kwargs)
  File "/usr/local/lib/python3.7/site-packages/requests/sessions.py", line 529, in request
    resp = self.send(prep, **send_kwargs)
  File "/usr/local/lib/python3.7/site-packages/requests/sessions.py", line 645, in send
    r = adapter.send(request, **kwargs)
  File "/usr/local/lib/python3.7/site-packages/requests/adapters.py", line 501, in send
    raise ConnectionError(err, request=request)
requests.exceptions.ConnectionError: ('Connection aborted.', ConnectionResetError(104, 'Connection reset by peer'))

1654669365503164284 1986239
1654669366910187253 1201539
1654669367705813734 1838061
1654669368306760772 4002777
1654669369605597607 1098209
1654669369892673745 8642375
1654669370121164597 2216433
1654669370326758489 5076233
1654669370611171567 8387795
1654669371205681713 2011329
1654669371419839669 8797667
1654669371713770982 9099924
1654669371973265691 5883087
1654669372473255076 1432484
1654669373893409027 1176732
1654669381616001878 7515985
1654669382408049271 3981927
1654669384222932143 1280713
1654669387710083251 3273310
1654669395401874524 7380309
1654669396212954794 6058012
1654669397637612963 1119021
1654669398714203122 5025334
1654669399724253744 4998424
1654669400335215048 2080220
1654669401800885293 1188060
1654669433542149866 3144342
Exception in thread 14:
Traceback (most recent call last):
  File "/usr/local/lib/python3.7/site-packages/urllib3/connection.py", line 175, in _new_conn
    (self._dns_host, self.port), self.timeout, **extra_kw
  File "/usr/local/lib/python3.7/site-packages/urllib3/util/connection.py", line 95, in create_connection
    raise err
  File "/usr/local/lib/python3.7/site-packages/urllib3/util/connection.py", line 85, in create_connection
    sock.connect(sa)
TimeoutError: [Errno 110] Connection timed out

During handling of the above exception, another exception occurred:

Traceback (most recent call last):
  File "/usr/local/lib/python3.7/site-packages/urllib3/connectionpool.py", line 710, in urlopen
    chunked=chunked,
  File "/usr/local/lib/python3.7/site-packages/urllib3/connectionpool.py", line 398, in _make_request
    conn.request(method, url, **httplib_request_kw)
  File "/usr/local/lib/python3.7/site-packages/urllib3/connection.py", line 239, in request
    super(HTTPConnection, self).request(method, url, body=body, headers=headers)
  File "/usr/local/lib/python3.7/http/client.py", line 1229, in request
    self._send_request(method, url, body, headers, encode_chunked)
  File "/usr/local/lib/python3.7/http/client.py", line 1275, in _send_request
    self.endheaders(body, encode_chunked=encode_chunked)
  File "/usr/local/lib/python3.7/http/client.py", line 1224, in endheaders
    self._send_output(message_body, encode_chunked=encode_chunked)
  File "/usr/local/lib/python3.7/http/client.py", line 1016, in _send_output
    self.send(msg)
  File "/usr/local/lib/python3.7/http/client.py", line 956, in send
    self.connect()
  File "/usr/local/lib/python3.7/site-packages/urllib3/connection.py", line 205, in connect
    conn = self._new_conn()
  File "/usr/local/lib/python3.7/site-packages/urllib3/connection.py", line 187, in _new_conn
    self, "Failed to establish a new connection: %s" % e
urllib3.exceptions.NewConnectionError: <urllib3.connection.HTTPConnection object at 0x7fea0878f6a0>: Failed to establish a new connection: [Errno 110] Connection timed out

During handling of the above exception, another exception occurred:

Traceback (most recent call last):
  File "/usr/local/lib/python3.7/site-packages/requests/adapters.py", line 450, in send
    timeout=timeout
  File "/usr/local/lib/python3.7/site-packages/urllib3/connectionpool.py", line 786, in urlopen
    method, url, error=e, _pool=self, _stacktrace=sys.exc_info()[2]
  File "/usr/local/lib/python3.7/site-packages/urllib3/util/retry.py", line 592, in increment
    raise MaxRetryError(_pool, url, error or ResponseError(cause))
urllib3.exceptions.MaxRetryError: HTTPConnectionPool(host='http-log-server', port=8001): Max retries exceeded with url: /line/29 (Caused by NewConnectionError('<urllib3.connection.HTTPConnection object at 0x7fea0878f6a0>: Failed to establish a new connection: [Errno 110] Connection timed out'))

During handling of the above exception, another exception occurred:

Traceback (most recent call last):
  File "/usr/local/lib/python3.7/threading.py", line 917, in _bootstrap_inner
    self.run()
  File "/usr/local/lib/python3.7/threading.py", line 865, in run
    self._target(*self._args, **self._kwargs)
  File "/app/models/stress_generator.py", line 43, in _kubernetes_job
    self._read_work(**kwargs)
  File "/app/models/stress_generator.py", line 89, in _read_work
    simple_http_client_get.perform(line_number=line_number)
  File "/app/models/simple_http_log_client.py", line 26, in perform
    return self._simple_requests_scenario(line_number)
  File "/app/models/simple_http_log_client.py", line 31, in _simple_requests_scenario
    return self.session.get(f"{self.api_url}/line/{line_number}")
  File "/usr/local/lib/python3.7/site-packages/requests/sessions.py", line 542, in get
    return self.request('GET', url, **kwargs)
  File "/usr/local/lib/python3.7/site-packages/requests/sessions.py", line 529, in request
    resp = self.send(prep, **send_kwargs)
  File "/usr/local/lib/python3.7/site-packages/requests/sessions.py", line 645, in send
    r = adapter.send(request, **kwargs)
  File "/usr/local/lib/python3.7/site-packages/requests/adapters.py", line 519, in send
    raise ConnectionError(e, request=request)
requests.exceptions.ConnectionError: HTTPConnectionPool(host='http-log-server', port=8001): Max retries exceeded with url: /line/29 (Caused by NewConnectionError('<urllib3.connection.HTTPConnection object at 0x7fea0878f6a0>: Failed to establish a new connection: [Errno 110] Connection timed out'))

